Workbook

Sheet Instrucciones
A1: Control Semanal Bocubi - Instrucciones
A2: Uso recomendado para analizar la empresa en 5-10 minutos cada semana.
A4: 1. Datos Semanales | B4: Rellenar una fila por semana. Es la hoja principal de datos. Idealmente la rellena Verónica recogiendo datos de cada responsable. | C4: Responsable | D4: Verónica
A6: 2. Dashboard | B6: Cambiar la semana en B3. El cuadro se actualiza con fórmulas y semáforos automáticos. | C6: Uso | D6: Borja + Verónica
A8: 3. Resumen Mensual | B8: Se alimenta de Datos Semanales por mes. Sirve para ver evolución mensual rápida. | C8: Uso | D8: Dirección
A10: 4. Plantilla Semana | B10: Formato vertical para revisión semanal. Puede imprimirse o usarse como guía de reunión. | C10: Uso | D10: Reunión semanal
A12: Regla clave | B12: Si un KPI está en Mal o Alerta, debe haber comentario y acción concreta. | C12: Principio | D12: Dato → decisión
B17: NO RELLENAR. ES AUTOMATICO

Sheet Datos Semanales
A1: Datos Semanales
A2: Rellenar una fila por semana. Las columnas blancas son datos de entrada; las naranjas son fórmulas.
X3: Capacidad Semanal | AA3: 45000
A4: Semana | B4: Mes | C4: Fecha inicio | D4: Fecha fin | E4: Nº de Pedidos | F4: Ticket medio | G4: Ventas (€) | H4: Objetivo ventas (€) | I4: % vs objetivo | J4: Ventas 2024 (€) | K4: % vs 2024 | L4: Nº Presus Enviados | M4: Nº Presus Confirmados | N4: Presu Confirm (€ ) | O4: % Presu Confirm | P4: Pedidos servidos (€) | Q4: Nº pedidos servidos | R4: Nº Pedidos fuera de plazo | S4: Pedidos atrasados (€) | T4: % fuera de plazo | U4: % incidencias | V4: Nº incidencias | W4: Nº Incidencias fuera de plazo | X4: Ticket medio | Y4: Nº Pedidos pendientes de servir | Z4: Pedidos pendientes de servir (€) | AA4: Carga fábrica (semanas) | AB4: Leads generados | AC4: CPL (€) | AD4: % conversión landing | AE4: Nº conversión lead→venta | AF4: % conversión lead→venta | AG4: Nº leads contactados | AH4: % leads contactados | AI4: Leads sin trabajar | AJ4: Leads reasignados | AK4: Responsable resumen | AL4: Comentario / causa principal | AM4: Acción de la semana
A5: 1 | F5: =IF(OR(E5="",E5=0,G5=""),"",G5/E5) | H5: 46500 | I5: =IF(OR(G5="",H5=""),"",G5/H5) | K5: =IF(OR(G5="",J5=""),"",G5/J5-1) | O5: =IF(OR(L5="",L5=0,M5=""),"",M5/L5) | T5: =IF(OR(Y5="",Y5=0,R5=""),"",R5/Y5) | U5: =IF(OR(E5="",E5=0,V5=""),"",V5/E5) | X5: =IF(OR(Y5="",Y5=0,Z5=""),"",Z5/Y5) | AA5: =IF(Z5="","",Z5/$AA$3) | AF5: =IF(OR(AB5="",AB5=0),"",AE5/AB5) | AH5: =IF(OR(AB5="",AB5=0,AG5=""),"",AG5/AB5) | AI5: =IF(OR(AB5="",AG5=""),"",AB5-AG5)
A6: 2 | F6: =IF(OR(E6="",E6=0,G6=""),"",G6/E6) | H6: 46500 | I6: =IF(OR(G6="",H6=""),"",G6/H6) | K6: =IF(OR(G6="",J6=""),"",G6/J6-1) | O6: =IF(OR(L6="",L6=0,M6=""),"",M6/L6) | T6: =IF(OR(Y6="",Y6=0,R6=""),"",R6/Y6) | U6: =IF(OR(E6="",E6=0,V6=""),"",V6/E6) | X6: =IF(OR(Y6="",Y6=0,Z6=""),"",Z6/Y6) | AA6: =IF(Z6="","",Z6/$AA$3) | AF6: =IF(OR(AB6="",AB6=0),"",AE6/AB6) | AH6: =IF(OR(AB6="",AB6=0,AG6=""),"",AG6/AB6) | AI6: =IF(OR(AB6="",AG6=""),"",AB6-AG6)
A7: 3 | F7: =IF(OR(E7="",E7=0,G7=""),"",G7/E7) | H7: 46500 | I7: =IF(OR(G7="",H7=""),"",G7/H7) | K7: =IF(OR(G7="",J7=""),"",G7/J7-1) | O7: =IF(OR(L7="",L7=0,M7=""),"",M7/L7) | T7: =IF(OR(Y7="",Y7=0,R7=""),"",R7/Y7) | U7: =IF(OR(E7="",E7=0,V7=""),"",V7/E7) | X7: =IF(OR(Y7="",Y7=0,Z7=""),"",Z7/Y7) | AA7: =IF(Z7="","",Z7/$AA$3) | AF7: =IF(OR(AB7="",AB7=0),"",AE7/AB7) | AH7: =IF(OR(AB7="",AB7=0,AG7=""),"",AG7/AB7) | AI7: =IF(OR(AB7="",AG7=""),"",AB7-AG7)
A8: 4 | F8: =IF(OR(E8="",E8=0,G8=""),"",G8/E8) | H8: 46500 | I8: =IF(OR(G8="",H8=""),"",G8/H8) | K8: =IF(OR(G8="",J8=""),"",G8/J8-1) | O8: =IF(OR(L8="",L8=0,M8=""),"",M8/L8) | T8: =IF(OR(Y8="",Y8=0,R8=""),"",R8/Y8) | U8: =IF(OR(E8="",E8=0,V8=""),"",V8/E8) | X8: =IF(OR(Y8="",Y8=0,Z8=""),"",Z8/Y8) | AA8: =IF(Z8="","",Z8/$AA$3) | AF8: =IF(OR(AB8="",AB8=0),"",AE8/AB8) | AH8: =IF(OR(AB8="",AB8=0,AG8=""),"",AG8/AB8) | AI8: =IF(OR(AB8="",AG8=""),"",AB8-AG8)
A9: 5 | F9: =IF(OR(E9="",E9=0,G9=""),"",G9/E9) | H9: 46500 | I9: =IF(OR(G9="",H9=""),"",G9/H9) | K9: =IF(OR(G9="",J9=""),"",G9/J9-1) | O9: =IF(OR(L9="",L9=0,M9=""),"",M9/L9) | T9: =IF(OR(Y9="",Y9=0,R9=""),"",R9/Y9) | U9: =IF(OR(E9="",E9=0,V9=""),"",V9/E9) | X9: =IF(OR(Y9="",Y9=0,Z9=""),"",Z9/Y9) | AA9: =IF(Z9="","",Z9/$AA$3) | AF9: =IF(OR(AB9="",AB9=0),"",AE9/AB9) | AH9: =IF(OR(AB9="",AB9=0,AG9=""),"",AG9/AB9) | AI9: =IF(OR(AB9="",AG9=""),"",AB9-AG9)
A10: 6 | F10: =IF(OR(E10="",E10=0,G10=""),"",G10/E10) | H10: 46500 | I10: =IF(OR(G10="",H10=""),"",G10/H10) | K10: =IF(OR(G10="",J10=""),"",G10/J10-1) | O10: =IF(OR(L10="",L10=0,M10=""),"",M10/L10) | T10: =IF(OR(Y10="",Y10=0,R10=""),"",R10/Y10) | U10: =IF(OR(E10="",E10=0,V10=""),"",V10/E10) | X10: =IF(OR(Y10="",Y10=0,Z10=""),"",Z10/Y10) | AA10: =IF(Z10="","",Z10/$AA$3) | AF10: =IF(OR(AB10="",AB10=0),"",AE10/AB10) | AH10: =IF(OR(AB10="",AB10=0,AG10=""),"",AG10/AB10) | AI10: =IF(OR(AB10="",AG10=""),"",AB10-AG10)
A11: 7 | F11: =IF(OR(E11="",E11=0,G11=""),"",G11/E11) | H11: 46500 | I11: =IF(OR(G11="",H11=""),"",G11/H11) | K11: =IF(OR(G11="",J11=""),"",G11/J11-1) | O11: =IF(OR(L11="",L11=0,M11=""),"",M11/L11) | T11: =IF(OR(Y11="",Y11=0,R11=""),"",R11/Y11) | U11: =IF(OR(E11="",E11=0,V11=""),"",V11/E11) | X11: =IF(OR(Y11="",Y11=0,Z11=""),"",Z11/Y11) | AA11: =IF(Z11="","",Z11/$AA$3) | AF11: =IF(OR(AB11="",AB11=0),"",AE11/AB11) | AH11: =IF(OR(AB11="",AB11=0,AG11=""),"",AG11/AB11) | AI11: =IF(OR(AB11="",AG11=""),"",AB11-AG11)
A12: 8 | F12: =IF(OR(E12="",E12=0,G12=""),"",G12/E12) | H12: 46500 | I12: =IF(OR(G12="",H12=""),"",G12/H12) | K12: =IF(OR(G12="",J12=""),"",G12/J12-1) | O12: =IF(OR(L12="",L12=0,M12=""),"",M12/L12) | T12: =IF(OR(Y12="",Y12=0,R12=""),"",R12/Y12) | U12: =IF(OR(E12="",E12=0,V12=""),"",V12/E12) | X12: =IF(OR(Y12="",Y12=0,Z12=""),"",Z12/Y12) | AA12: =IF(Z12="","",Z12/$AA$3) | AF12: =IF(OR(AB12="",AB12=0),"",AE12/AB12) | AH12: =IF(OR(AB12="",AB12=0,AG12=""),"",AG12/AB12) | AI12: =IF(OR(AB12="",AG12=""),"",AB12-AG12)
A13: 9 | F13: =IF(OR(E13="",E13=0,G13=""),"",G13/E13) | H13: 46500 | I13: =IF(OR(G13="",H13=""),"",G13/H13) | K13: =IF(OR(G13="",J13=""),"",G13/J13-1) | O13: =IF(OR(L13="",L13=0,M13=""),"",M13/L13) | T13: =IF(OR(Y13="",Y13=0,R13=""),"",R13/Y13) | U13: =IF(OR(E13="",E13=0,V13=""),"",V13/E13) | X13: =IF(OR(Y13="",Y13=0,Z13=""),"",Z13/Y13) | AA13: =IF(Z13="","",Z13/$AA$3) | AF13: =IF(OR(AB13="",AB13=0),"",AE13/AB13) | AH13: =IF(OR(AB13="",AB13=0,AG13=""),"",AG13/AB13) | AI13: =IF(OR(AB13="",AG13=""),"",AB13-AG13)
A14: 10 | F14: =IF(OR(E14="",E14=0,G14=""),"",G14/E14) | H14: 46500 | I14: =IF(OR(G14="",H14=""),"",G14/H14) | K14: =IF(OR(G14="",J14=""),"",G14/J14-1) | O14: =IF(OR(L14="",L14=0,M14=""),"",M14/L14) | T14: =IF(OR(Y14="",Y14=0,R14=""),"",R14/Y14) | U14: =IF(OR(E14="",E14=0,V14=""),"",V14/E14) | X14: =IF(OR(Y14="",Y14=0,Z14=""),"",Z14/Y14) | AA14: =IF(Z14="","",Z14/$AA$3) | AF14: =IF(OR(AB14="",AB14=0),"",AE14/AB14) | AH14: =IF(OR(AB14="",AB14=0,AG14=""),"",AG14/AB14) | AI14: =IF(OR(AB14="",AG14=""),"",AB14-AG14)
A15: 11 | F15: =IF(OR(E15="",E15=0,G15=""),"",G15/E15) | H15: 46500 | I15: =IF(OR(G15="",H15=""),"",G15/H15) | K15: =IF(OR(G15="",J15=""),"",G15/J15-1) | O15: =IF(OR(L15="",L15=0,M15=""),"",M15/L15) | T15: =IF(OR(Y15="",Y15=0,R15=""),"",R15/Y15) | U15: =IF(OR(E15="",E15=0,V15=""),"",V15/E15) | X15: =IF(OR(Y15="",Y15=0,Z15=""),"",Z15/Y15) | AA15: =IF(Z15="","",Z15/$AA$3) | AF15: =IF(OR(AB15="",AB15=0),"",AE15/AB15) | AH15: =IF(OR(AB15="",AB15=0,AG15=""),"",AG15/AB15) | AI15: =IF(OR(AB15="",AG15=""),"",AB15-AG15)
A16: 12 | F16: =IF(OR(E16="",E16=0,G16=""),"",G16/E16) | H16: 46500 | I16: =IF(OR(G16="",H16=""),"",G16/H16) | K16: =IF(OR(G16="",J16=""),"",G16/J16-1) | O16: =IF(OR(L16="",L16=0,M16=""),"",M16/L16) | T16: =IF(OR(Y16="",Y16=0,R16=""),"",R16/Y16) | U16: =IF(OR(E16="",E16=0,V16=""),"",V16/E16) | X16: =IF(OR(Y16="",Y16=0,Z16=""),"",Z16/Y16) | AA16: =IF(Z16="","",Z16/$AA$3) | AF16: =IF(OR(AB16="",AB16=0),"",AE16/AB16) | AI16: =IF(OR(AB16="",AG16=""),"",AB16-AG16)
A17: 13 | F17: =IF(OR(E17="",E17=0,G17=""),"",G17/E17) | H17: 46500 | I17: =IF(OR(G17="",H17=""),"",G17/H17) | K17: =IF(OR(G17="",J17=""),"",G17/J17-1) | O17: =IF(OR(L17="",L17=0,M17=""),"",M17/L17) | T17: =IF(OR(Y17="",Y17=0,R17=""),"",R17/Y17) | U17: =IF(OR(E17="",E17=0,V17=""),"",V17/E17) | X17: =IF(OR(Y17="",Y17=0,Z17=""),"",Z17/Y17) | AA17: =IF(Z17="","",Z17/$AA$3) | AF17: =IF(OR(AB17="",AB17=0),"",AE17/AB17) | AH17: =IF(OR(AB17="",AB17=0,AG17=""),"",AG17/AB17) | AI17: =IF(OR(AB17="",AG17=""),"",AB17-AG17)
A18: 14 | F18: =IF(OR(E18="",E18=0,G18=""),"",G18/E18) | H18: 46500 | I18: =IF(OR(G18="",H18=""),"",G18/H18) | K18: =IF(OR(G18="",J18=""),"",G18/J18-1) | O18: =IF(OR(L18="",L18=0,M18=""),"",M18/L18) | T18: =IF(OR(Y18="",Y18=0,R18=""),"",R18/Y18) | U18: =IF(OR(E18="",E18=0,V18=""),"",V18/E18) | X18: =IF(OR(Y18="",Y18=0,Z18=""),"",Z18/Y18) | AA18: =IF(Z18="","",Z18/$AA$3) | AF18: =IF(OR(AB18="",AB18=0),"",AE18/AB18) | AH18: =IF(OR(AB18="",AB18=0,AG18=""),"",AG18/AB18) | AI18: =IF(OR(AB18="",AG18=""),"",AB18-AG18)
A19: 15 | F19: =IF(OR(E19="",E19=0,G19=""),"",G19/E19) | H19: 46500 | I19: =IF(OR(G19="",H19=""),"",G19/H19) | K19: =IF(OR(G19="",J19=""),"",G19/J19-1) | O19: =IF(OR(L19="",L19=0,M19=""),"",M19/L19) | T19: =IF(OR(Y19="",Y19=0,R19=""),"",R19/Y19) | U19: =IF(OR(E19="",E19=0,V19=""),"",V19/E19) | X19: =IF(OR(Y19="",Y19=0,Z19=""),"",Z19/Y19) | AA19: =IF(Z19="","",Z19/$AA$3) | AF19: =IF(OR(AB19="",AB19=0),"",AE19/AB19) | AH19: =IF(OR(AB19="",AB19=0,AG19=""),"",AG19/AB19) | AI19: =IF(OR(AB19="",AG19=""),"",AB19-AG19)
A20: 16 | F20: =IF(OR(E20="",E20=0,G20=""),"",G20/E20) | H20: 46500 | I20: =IF(OR(G20="",H20=""),"",G20/H20) | K20: =IF(OR(G20="",J20=""),"",G20/J20-1) | O20: =IF(OR(L20="",L20=0,M20=""),"",M20/L20) | T20: =IF(OR(Y20="",Y20=0,R20=""),"",R20/Y20) | U20: =IF(OR(E20="",E20=0,V20=""),"",V20/E20) | X20: =IF(OR(Y20="",Y20=0,Z20=""),"",Z20/Y20) | AA20: =IF(Z20="","",Z20/$AA$3) | AF20: =IF(OR(AB20="",AB20=0),"",AE20/AB20) | AH20: =IF(OR(AB20="",AB20=0,AG20=""),"",AG20/AB20) | AI20: =IF(OR(AB20="",AG20=""),"",AB20-AG20)
A21: 17 | B21: Abril | C21: 46130 | D21: 46136 | E21: 21 | F21: =IF(OR(E21="",E21=0,G21=""),"",G21/E21) -> 2880.9524 | G21: 60500 | H21: 46500 | I21: =IF(OR(G21="",H21=""),"",G21/H21) -> 1.3010753 | J21: 45700 | K21: =IF(OR(G21="",J21=""),"",G21/J21-1) -> 0.3238512 | O21: =IF(OR(L21="",L21=0,M21=""),"",M21/L21) | P21: 30900 | T21: =IF(OR(Y21="",Y21=0,R21=""),"",R21/Y21) | U21: =IF(OR(E21="",E21=0,V21=""),"",V21/E21) -> 0.57142857 | V21: 12 | X21: =IF(OR(Y21="",Y21=0,Z21=""),"",Z21/Y21) | Z21: 171524.64 | AA21: =IF(Z21="","",Z21/$AA$3) -> 3.8116587 | AB21: 54 | AE21: 1 | AF21: =IF(OR(AB21="",AB21=0),"",AE21/AB21) -> 0.018518519 | AH21: =IF(OR(AB21="",AB21=0,AG21=""),"",AG21/AB21) | AI21: =IF(OR(AB21="",AG21=""),"",AB21-AG21) | AK21: Verónica
A22: 18 | B22: Abril | C22: 46139 | D22: 46142 | E22: =29-2 -> 27 | F22: =IF(OR(E22="",E22=0,G22=""),"",G22/E22) -> 1677.5511 | G22: 45293.88 | H22: 46500 | I22: =IF(OR(G22="",H22=""),"",G22/H22) -> 0.97406194 | J22: 52700 | K22: =IF(OR(G22="",J22=""),"",G22/J22-1) -> -0.14053359 | O22: =IF(OR(L22="",L22=0,M22=""),"",M22/L22) | P22: 52888.83 | R22: 0 | S22: 0 | T22: =IF(OR(Y22="",Y22=0,R22=""),"",R22/Y22) -> 0 | U22: =IF(OR(E22="",E22=0,V22=""),"",V22/E22) | X22: =IF(OR(Y22="",Y22=0,Z22=""),"",Z22/Y22) -> 1986.0159 | Y22: =92-7 -> 85 | Z22: 168811.35 | AA22: =IF(Z22="","",Z22/$AA$3) -> 3.7513633 | AB22: 53 | AE22: 1 | AF22: =IF(OR(AB22="",AB22=0),"",AE22/AB22) -> 0.018867925 | AG22: 23 | AH22: =IF(OR(AB22="",AB22=0,AG22=""),"",AG22/AB22) -> 0.43396226 | AI22: =IF(OR(AB22="",AG22=""),"",AB22-AG22) -> 30 | AK22: Verónica
A23: 19 | B23: Mayo | C23: 46146 | D23: 46150 | E23: 32 | F23: =IF(OR(E23="",E23=0,G23=""),"",G23/E23) -> 1863.7494 | G23: 59639.98 | H23: 46500 | I23: =IF(OR(G23="",H23=""),"",G23/H23) -> 1.2825802 | J23: 21028 | K23: =IF(OR(G23="",J23=""),"",G23/J23-1) -> 1.8362174 | M23: 7 | N23: 19221.26 | O23: =IF(OR(L23="",L23=0,M23=""),"",M23/L23) | P23: 35407 | Q23: 22 | T23: =IF(OR(Y23="",Y23=0,R23=""),"",R23/Y23) | U23: =IF(OR(E23="",E23=0,V23=""),"",V23/E23) | X23: =IF(OR(Y23="",Y23=0,Z23=""),"",Z23/Y23) | AA23: =IF(Z23="","",Z23/$AA$3) | AB23: 53 | AC23: 15.07 | AF23: =IF(OR(AB23="",AB23=0),"",AE23/AB23) -> 0 | AH23: =IF(OR(AB23="",AB23=0,AG23=""),"",AG23/AB23) | AI23: =IF(OR(AB23="",AG23=""),"",AB23-AG23) | AK23: Verónica
A24: 20 | B24: Mayo | C24: 46153 | D24: 46157 | E24: 19 | F24: =IF(OR(E24="",E24=0,G24=""),"",G24/E24) -> 1027.04 | G24: 19513.76 | H24: 46500 | I24: =IF(OR(G24="",H24=""),"",G24/H24) -> 0.41965075 | J24: 46867 | K24: =IF(OR(G24="",J24=""),"",G24/J24-1) -> -0.58363539 | L24: 11 | M24: 4 | N24: 3715.56 | O24: =IF(OR(L24="",L24=0,M24=""),"",M24/L24) -> 0.36363636 | P24: 38803 | Q24: 25 | R24: 12 | S24: 24321 | T24: =IF(OR(Y24="",Y24=0,R24=""),"",R24/Y24) -> 0.13636364 | U24: =IF(OR(E24="",E24=0,V24=""),"",V24/E24) -> 0.68421053 | V24: 13 | X24: =IF(OR(Y24="",Y24=0,Z24=""),"",Z24/Y24) -> 1951.5455 | Y24: 88 | Z24: 171736 | AA24: =IF(Z24="","",Z24/$AA$3) -> 3.8163556 | AB24: 57 | AC24: 14.22 | AD24: 0.0232 | AE24: 4 | AF24: =IF(OR(AB24="",AB24=0),"",AE24/AB24) -> 0.070175439 | AG24: 22 | AH24: =IF(OR(AB24="",AB24=0,AG24=""),"",AG24/AB24) -> 0.38596491 | AI24: =IF(OR(AB24="",AG24=""),"",AB24-AG24) -> 35 | AK24: Verónica
A25: 21 | B25: Mayo | C25: 46160 | D25: 46164 | E25: 27 | F25: =IF(OR(E25="",E25=0,G25=""),"",G25/E25) -> 1361.97 | G25: 36773.19 | H25: 46500 | I25: =IF(OR(G25="",H25=""),"",G25/H25) -> 0.79082129 | J25: 62192 | K25: =IF(OR(G25="",J25=""),"",G25/J25-1) -> -0.40871511 | L25: 14 | M25: 3 | N25: 5918.79 | O25: =IF(OR(L25="",L25=0,M25=""),"",M25/L25) -> 0.21428571 | P25: 42766 | Q25: 32 | R25: 2 | S25: 1992.15 | T25: =IF(OR(Y25="",Y25=0,R25=""),"",R25/Y25) -> 0.023529412 | U25: =IF(OR(E25="",E25=0,V25=""),"",V25/E25) -> 0.2962963 | V25: 8 | W25: 1 | X25: =IF(OR(Y25="",Y25=0,Z25=""),"",Z25/Y25) -> 2058.786 | Y25: 85 | Z25: 174996.81 | AA25: =IF(Z25="","",Z25/$AA$3) -> 3.888818 | AB25: 46 | AC25: 13.05 | AD25: 0.0317 | AE25: 2 | AF25: =IF(OR(AB25="",AB25=0),"",AE25/AB25) -> 0.043478261 | AG25: 16 | AH25: =IF(OR(AB25="",AB25=0,AG25=""),"",AG25/AB25) -> 0.34782609 | AI25: =IF(OR(AB25="",AG25=""),"",AB25-AG25) -> 30 | AK25: Verónica
A26: 22 | B26: Mayo | C26: 46167 | D26: 46171 | E26: 30 | F26: =IF(OR(E26="",E26=0,G26=""),"",G26/E26) -> 1738.9147 | G26: 52167.44 | H26: 46500 | I26: =IF(OR(G26="",H26=""),"",G26/H26) -> 1.1218804 | J26: =51666.71+38795 -> 90461.71 | K26: =IF(OR(G26="",J26=""),"",G26/J26-1) -> -0.42332021 | L26: 9 | M26: 4 | N26: 11084.3 | O26: =IF(OR(L26="",L26=0,M26=""),"",M26/L26) -> 0.44444444 | P26: 83844 | Q26: 41 | R26: 5 | S26: 4029.66 | T26: =IF(OR(Y26="",Y26=0,R26=""),"",R26/Y26) -> 0.067567568 | U26: =IF(OR(E26="",E26=0,V26=""),"",V26/E26) -> 0.23333333 | V26: 7 | W26: 3 | X26: =IF(OR(Y26="",Y26=0,Z26=""),"",Z26/Y26) -> 1945.2224 | Y26: 74 | Z26: 143946.46 | AA26: =IF(Z26="","",Z26/$AA$3) -> 3.1988102 | AF26: =IF(OR(AB26="",AB26=0),"",AE26/AB26) | AH26: =IF(OR(AB26="",AB26=0,AG26=""),"",AG26/AB26) | AI26: =IF(OR(AB26="",AG26=""),"",AB26-AG26) | AK26: Verónica | AL26: Varios pendiente por falta de pago.
A27: 23 | B27: Junio | C27: 46174 | D27: 46178 | E27: 22 | F27: =IF(OR(E27="",E27=0,G27=""),"",G27/E27) -> 1487.6818 | G27: 32729 | H27: 46500 | I27: =IF(OR(G27="",H27=""),"",G27/H27) -> 0.70384946 | J27: 53918 | K27: =IF(OR(G27="",J27=""),"",G27/J27-1) -> -0.39298564 | L27: 19 | M27: 2 | N27: 4463 | O27: =IF(OR(L27="",L27=0,M27=""),"",M27/L27) -> 0.10526316 | P27: 33317 | Q27: 19 | R27: 1 | S27: 1638 | T27: =IF(OR(Y27="",Y27=0,R27=""),"",R27/Y27) -> 0.013157895 | U27: =IF(OR(E27="",E27=0,V27=""),"",V27/E27) -> 0.40909091 | V27: 9 | W27: 1 | X27: =IF(OR(Y27="",Y27=0,Z27=""),"",Z27/Y27) -> 1805.5658 | Y27: 76 | Z27: 137223 | AA27: =IF(Z27="","",Z27/$AA$3) -> 3.0494 | AF27: =IF(OR(AB27="",AB27=0),"",AE27/AB27) | AH27: =IF(OR(AB27="",AB27=0,AG27=""),"",AG27/AB27) | AI27: =IF(OR(AB27="",AG27=""),"",AB27-AG27)
A28: 24 | B28: Junio | C28: 46181 | D28: 46185 | E28: 26 | F28: =IF(OR(E28="",E28=0,G28=""),"",G28/E28) -> 1285 | G28: 33410 | H28: 46500 | I28: =IF(OR(G28="",H28=""),"",G28/H28) -> 0.71849462 | J28: 53947 | K28: =IF(OR(G28="",J28=""),"",G28/J28-1) -> -0.38068845 | L28: 14 | M28: 6 | N28: 11686 | O28: =IF(OR(L28="",L28=0,M28=""),"",M28/L28) -> 0.42857143 | P28: 33162 | Q28: 24 | R28: 2 | S28: 13691 | T28: =IF(OR(Y28="",Y28=0,R28=""),"",R28/Y28) -> 0.025 | U28: =IF(OR(E28="",E28=0,V28=""),"",V28/E28) | W28: 5 | X28: =IF(OR(Y28="",Y28=0,Z28=""),"",Z28/Y28) -> 1831.9875 | Y28: 80 | Z28: 146559 | AA28: =IF(Z28="","",Z28/$AA$3) -> 3.2568667 | AF28: =IF(OR(AB28="",AB28=0),"",AE28/AB28) | AH28: =IF(OR(AB28="",AB28=0,AG28=""),"",AG28/AB28) | AI28: =IF(OR(AB28="",AG28=""),"",AB28-AG28)
A29: 25 | B29: Junio | C29: 46188 | D29: 46192 | E29: 28 | F29: =IF(OR(E29="",E29=0,G29=""),"",G29/E29) -> 1650 | G29: 46200 | H29: 46500 | I29: =IF(OR(G29="",H29=""),"",G29/H29) -> 0.99354839 | J29: 59204 | K29: =IF(OR(G29="",J29=""),"",G29/J29-1) -> -0.21964732 | L29: 16 | M29: 7 | N29: 12035 | O29: =IF(OR(L29="",L29=0,M29=""),"",M29/L29) -> 0.4375 | P29: 27332 | Q29: 29 | R29: 3 | S29: 5017 | T29: =IF(OR(Y29="",Y29=0,R29=""),"",R29/Y29) -> 0.038461538 | U29: =IF(OR(E29="",E29=0,V29=""),"",V29/E29) | W29: 1 | X29: =IF(OR(Y29="",Y29=0,Z29=""),"",Z29/Y29) -> 1986.3333 | Y29: 78 | Z29: 154934 | AA29: =IF(Z29="","",Z29/$AA$3) -> 3.4429778 | AF29: =IF(OR(AB29="",AB29=0),"",AE29/AB29) | AH29: =IF(OR(AB29="",AB29=0,AG29=""),"",AG29/AB29) | AI29: =IF(OR(AB29="",AG29=""),"",AB29-AG29)
A30: 26 | B30: Junio | C30: 46195 | D30: 46199 | E30: 16 | F30: =IF(OR(E30="",E30=0,G30=""),"",G30/E30) -> 1250 | G30: 20000 | H30: 46500 | I30: =IF(OR(G30="",H30=""),"",G30/H30) -> 0.43010753 | J30: 36240 | K30: =IF(OR(G30="",J30=""),"",G30/J30-1) -> -0.44812362 | L30: 17 | M30: 5 | N30: 5577 | O30: =IF(OR(L30="",L30=0,M30=""),"",M30/L30) -> 0.29411765 | P30: 53084 | Q30: 30 | R30: 4 | S30: 9956.86 | T30: =IF(OR(Y30="",Y30=0,R30=""),"",R30/Y30) -> 0.06557377 | U30: =IF(OR(E30="",E30=0,V30=""),"",V30/E30) -> 0.1875 | V30: 3 | W30: 4 | X30: =IF(OR(Y30="",Y30=0,Z30=""),"",Z30/Y30) -> 2103.1475 | Y30: 61 | Z30: 128292 | AA30: =IF(Z30="","",Z30/$AA$3) -> 2.8509333 | AF30: =IF(OR(AB30="",AB30=0),"",AE30/AB30) | AH30: =IF(OR(AB30="",AB30=0,AG30=""),"",AG30/AB30) | AI30: =IF(OR(AB30="",AG30=""),"",AB30-AG30)
A31: 27 | B31: Junio | C31: 46202 | D31: 46206 | E31: 29 | F31: =IF(OR(E31="",E31=0,G31=""),"",G31/E31) -> 1195.8621 | G31: 34680 | H31: 46500 | I31: =IF(OR(G31="",H31=""),"",G31/H31) -> 0.74580645 | K31: =IF(OR(G31="",J31=""),"",G31/J31-1) | L31: 14 | M31: 5 | N31: 4688.38 | O31: =IF(OR(L31="",L31=0,M31=""),"",M31/L31) -> 0.35714286 | P31: 48077 | Q31: 28 | R31: 3 | S31: 24163.25 | T31: =IF(OR(Y31="",Y31=0,R31=""),"",R31/Y31) | U31: =IF(OR(E31="",E31=0,V31=""),"",V31/E31) -> 0.5862069 | V31: 17 | W31: 0 | X31: =IF(OR(Y31="",Y31=0,Z31=""),"",Z31/Y31) | AA31: =IF(Z31="","",Z31/$AA$3) | AF31: =IF(OR(AB31="",AB31=0),"",AE31/AB31) | AH31: =IF(OR(AB31="",AB31=0,AG31=""),"",AG31/AB31) | AI31: =IF(OR(AB31="",AG31=""),"",AB31-AG31)
A32: 28 | B32: Julio | C32: 46209 | D32: 46213 | E32: 16 | F32: =IF(OR(E32="",E32=0,G32=""),"",G32/E32) -> 678.75 | G32: 10860 | H32: 46500 | I32: =IF(OR(G32="",H32=""),"",G32/H32) -> 0.23354839 | J32: 56101 | K32: =IF(OR(G32="",J32=""),"",G32/J32-1) -> -0.80642056 | L32: 17 | M32: 1 | N32: 195 | O32: =IF(OR(L32="",L32=0,M32=""),"",M32/L32) -> 0.058823529 | P32: 35599 | Q32: 35 | R32: 4 | S32: 14409.92 | T32: =IF(OR(Y32="",Y32=0,R32=""),"",R32/Y32) -> 0.078431373 | U32: =IF(OR(E32="",E32=0,V32=""),"",V32/E32) -> 0.1875 | V32: 3 | W32: 3 | X32: =IF(OR(Y32="",Y32=0,Z32=""),"",Z32/Y32) -> 2192.3065 | Y32: 51 | Z32: 111807.63 | AA32: =IF(Z32="","",Z32/$AA$3) -> 2.484614 | AF32: =IF(OR(AB32="",AB32=0),"",AE32/AB32) | AH32: =IF(OR(AB32="",AB32=0,AG32=""),"",AG32/AB32) | AI32: =IF(OR(AB32="",AG32=""),"",AB32-AG32)
A33: 29 | B33: Julio | C33: 46216 | D33: 46220 | E33: 10 | F33: =IF(OR(E33="",E33=0,G33=""),"",G33/E33) -> 1535 | G33: 15350 | H33: 46500 | I33: =IF(OR(G33="",H33=""),"",G33/H33) -> 0.33010753 | J33: 33072 | K33: =IF(OR(G33="",J33=""),"",G33/J33-1) -> -0.53586115 | L33: 10 | M33: 5 | N33: 7029 | O33: =IF(OR(L33="",L33=0,M33=""),"",M33/L33) -> 0.5 | P33: 34407 | Q33: 18 | R33: 0 | T33: =IF(OR(Y33="",Y33=0,R33=""),"",R33/Y33) -> 0 | U33: =IF(OR(E33="",E33=0,V33=""),"",V33/E33) -> 1.5 | V33: 15 | W33: 0 | X33: =IF(OR(Y33="",Y33=0,Z33=""),"",Z33/Y33) -> 1526 | Y33: 48 | Z33: 73248 | AA33: =IF(Z33="","",Z33/$AA$3) -> 1.6277333 | AF33: =IF(OR(AB33="",AB33=0),"",AE33/AB33) | AH33: =IF(OR(AB33="",AB33=0,AG33=""),"",AG33/AB33) | AI33: =IF(OR(AB33="",AG33=""),"",AB33-AG33)
A34: 30 | B34: Julio | C34: 46223 | D34: 46227 | E34: 10 | F34: =IF(OR(E34="",E34=0,G34=""),"",G34/E34) -> 1399.5 | G34: 13995 | H34: 46500 | I34: =IF(OR(G34="",H34=""),"",G34/H34) -> 0.30096774 | J34: 29004 | K34: =IF(OR(G34="",J34=""),"",G34/J34-1) -> -0.51748035 | L34: 14 | M34: 3 | N34: 5411 | O34: =IF(OR(L34="",L34=0,M34=""),"",M34/L34) -> 0.21428571 | P34: 18162 | Q34: 18 | R34: 9 | S34: 31021.75 | T34: =IF(OR(Y34="",Y34=0,R34=""),"",R34/Y34) -> 0.2195122 | U34: =IF(OR(E34="",E34=0,V34=""),"",V34/E34) -> 1 | V34: 10 | W34: 6 | X34: =IF(OR(Y34="",Y34=0,Z34=""),"",Z34/Y34) -> 1681.2927 | Y34: 41 | Z34: 68933 | AA34: =IF(Z34="","",Z34/$AA$3) -> 1.5318444 | AF34: =IF(OR(AB34="",AB34=0),"",AE34/AB34) | AH34: =IF(OR(AB34="",AB34=0,AG34=""),"",AG34/AB34) | AI34: =IF(OR(AB34="",AG34=""),"",AB34-AG34)
A35: 31 | B35: Julio | C35: 46230 | D35: 46234 | E35: 15 | F35: =IF(OR(E35="",E35=0,G35=""),"",G35/E35) -> 1355.3333 | G35: 20330 | H35: 46500 | I35: =IF(OR(G35="",H35=""),"",G35/H35) -> 0.4372043 | J35: 61595 | K35: =IF(OR(G35="",J35=""),"",G35/J35-1) -> -0.66994074 | O35: =IF(OR(L35="",L35=0,M35=""),"",M35/L35) | T35: =IF(OR(Y35="",Y35=0,R35=""),"",R35/Y35) | U35: =IF(OR(E35="",E35=0,V35=""),"",V35/E35) | X35: =IF(OR(Y35="",Y35=0,Z35=""),"",Z35/Y35) | AA35: =IF(Z35="","",Z35/$AA$3) | AF35: =IF(OR(AB35="",AB35=0),"",AE35/AB35) | AH35: =IF(OR(AB35="",AB35=0,AG35=""),"",AG35/AB35) | AI35: =IF(OR(AB35="",AG35=""),"",AB35-AG35)
A36: 32 | B36: Agosto | C36: 46237 | D36: 46243 | E36: 0 | F36: =IF(OR(E36="",E36=0,G36=""),"",G36/E36) | G36: 0 | H36: 85000 | I36: =IF(OR(G36="",H36=""),"",G36/H36) -> 0 | K36: =IF(OR(G36="",J36=""),"",G36/J36-1) | O36: =IF(OR(L36="",L36=0,M36=""),"",M36/L36) | T36: =IF(OR(Y36="",Y36=0,R36=""),"",R36/Y36) | U36: =IF(OR(E36="",E36=0,V36=""),"",V36/E36) | X36: =IF(OR(Y36="",Y36=0,Z36=""),"",Z36/Y36) | AA36: =IF(Z36="","",Z36/$AA$3) | AF36: =IF(OR(AB36="",AB36=0),"",AE36/AB36) | AH36: =IF(OR(AB36="",AB36=0,AG36=""),"",AG36/AB36) | AI36: =IF(OR(AB36="",AG36=""),"",AB36-AG36)
A37: 33 | B37: Agosto | C37: 46244 | D37: 46250 | E37: 0 | F37: =IF(OR(E37="",E37=0,G37=""),"",G37/E37) | G37: 0 | H37: 46500 | I37: =IF(OR(G37="",H37=""),"",G37/H37) -> 0 | K37: =IF(OR(G37="",J37=""),"",G37/J37-1) | O37: =IF(OR(L37="",L37=0,M37=""),"",M37/L37) | T37: =IF(OR(Y37="",Y37=0,R37=""),"",R37/Y37) | U37: =IF(OR(E37="",E37=0,V37=""),"",V37/E37) | X37: =IF(OR(Y37="",Y37=0,Z37=""),"",Z37/Y37) | AA37: =IF(Z37="","",Z37/$AA$3) | AF37: =IF(OR(AB37="",AB37=0),"",AE37/AB37) | AH37: =IF(OR(AB37="",AB37=0,AG37=""),"",AG37/AB37) | AI37: =IF(OR(AB37="",AG37=""),"",AB37-AG37)
A38: 34 | B38: Agosto | C38: 46251 | D38: 46257 | E38: 0 | F38: =IF(OR(E38="",E38=0,G38=""),"",G38/E38) | G38: 0 | H38: 46500 | I38: =IF(OR(G38="",H38=""),"",G38/H38) -> 0 | K38: =IF(OR(G38="",J38=""),"",G38/J38-1) | O38: =IF(OR(L38="",L38=0,M38=""),"",M38/L38) | T38: =IF(OR(Y38="",Y38=0,R38=""),"",R38/Y38) | U38: =IF(OR(E38="",E38=0,V38=""),"",V38/E38) | X38: =IF(OR(Y38="",Y38=0,Z38=""),"",Z38/Y38) | AA38: =IF(Z38="","",Z38/$AA$3) | AF38: =IF(OR(AB38="",AB38=0),"",AE38/AB38) | AH38: =IF(OR(AB38="",AB38=0,AG38=""),"",AG38/AB38) | AI38: =IF(OR(AB38="",AG38=""),"",AB38-AG38)
A39: 35 | B39: Agosto | C39: 46258 | D39: 46264 | E39: 0 | F39: =IF(OR(E39="",E39=0,G39=""),"",G39/E39) | G39: 49990 | H39: 46500 | I39: =IF(OR(G39="",H39=""),"",G39/H39) -> 1.0750538 | J39: 85514 | K39: =IF(OR(G39="",J39=""),"",G39/J39-1) -> -0.41541736 | O39: =IF(OR(L39="",L39=0,M39=""),"",M39/L39) | T39: =IF(OR(Y39="",Y39=0,R39=""),"",R39/Y39) | U39: =IF(OR(E39="",E39=0,V39=""),"",V39/E39) | X39: =IF(OR(Y39="",Y39=0,Z39=""),"",Z39/Y39) | AA39: =IF(Z39="","",Z39/$AA$3) | AF39: =IF(OR(AB39="",AB39=0),"",AE39/AB39) | AH39: =IF(OR(AB39="",AB39=0,AG39=""),"",AG39/AB39) | AI39: =IF(OR(AB39="",AG39=""),"",AB39-AG39)
A40: 36 | B40: Septiembre | C40: 46266 | D40: 46269 | E40: 27 | F40: =IF(OR(E40="",E40=0,G40=""),"",G40/E40) -> 1028.5185 | G40: 27770 | H40: 46500 | I40: =IF(OR(G40="",H40=""),"",G40/H40) -> 0.5972043 | J40: 32505 | K40: =IF(OR(G40="",J40=""),"",G40/J40-1) -> -0.1456699 | O40: =IF(OR(L40="",L40=0,M40=""),"",M40/L40) | T40: =IF(OR(Y40="",Y40=0,R40=""),"",R40/Y40) | U40: =IF(OR(E40="",E40=0,V40=""),"",V40/E40) | X40: =IF(OR(Y40="",Y40=0,Z40=""),"",Z40/Y40) | AA40: =IF(Z40="","",Z40/$AA$3) | AF40: =IF(OR(AB40="",AB40=0),"",AE40/AB40) | AH40: =IF(OR(AB40="",AB40=0,AG40=""),"",AG40/AB40) | AI40: =IF(OR(AB40="",AG40=""),"",AB40-AG40)
...

Sheet Dashboard
A1: Dashboard Semanal
A2: Cambia la semana en B3. El semáforo se calcula automáticamente con reglas simples.
A3: Semana a analizar | B3: 18
A5: KPI | B5: Valor Actual | C5: Objetivo | D5: Semana Anterior | E5: Evolución | F5: Estado | G5: Comentario / Acción recomendada
A6: Ventas (€) | B6: =IFERROR(INDEX('Datos Semanales'!$G$5:$G$57,MATCH($B$3,'Datos Semanales'!$A$5:$A$57,0)),"") -> 45293.88 | C6: 46000 | D6: =IFERROR(INDEX('Datos Semanales'!$G$5:$G$57,MATCH($B$3-1,'Datos Semanales'!$A$5:$A$57,0)),"") -> 60500 | E6: =IFERROR(B6-D6,"") -> -15206.12 | F6: =IF(B6="","",IF(B6>=C6,"Bien",IF(B6>=C6*0.85,"Alerta","Mal"))) -> Alerta
A7: % vs objetivo ventas | B7: =IFERROR(INDEX('Datos Semanales'!$I$5:$I$57,MATCH($B$3,'Datos Semanales'!$A$5:$A$57,0)),"") -> 0.97406194 | C7: 1 | D7: =IFERROR(INDEX('Datos Semanales'!$I$5:$I$57,MATCH($B$3-1,'Datos Semanales'!$A$5:$A$57,0)),"") -> 1.3010753 | E7: =IFERROR(B7-D7,"") -> -0.32701333 | F7: =IF(B7="","",IF(B7>=C7,"Bien",IF(B7>=C7*0.85,"Alerta","Mal"))) -> Alerta
A8: Pedidos Servidos | B8: =IFERROR(VLOOKUP($B$3,'Datos Semanales'!A:Y,21,FALSE),"") | C8: 43000 | F8: =IF(B8="","",IF(B8>=C8,"Bien",IF(B8>=C8*0.85,"Alerta","Mal")))
A9: Leads generados | B9: =IFERROR(INDEX('Datos Semanales'!$AB$5:$AB$57,MATCH($B$3,'Datos Semanales'!$A$5:$A$57,0)),"") -> 53 | C9: 75 | D9: =IFERROR(INDEX('Datos Semanales'!$AB$5:$AB$57,MATCH($B$3-1,'Datos Semanales'!$A$5:$A$57,0)),"") -> 54 | E9: =IFERROR(B9-D9,"") -> -1 | F9: =IF(B9="","",IF(B9>=C9,"Bien",IF(B9>=C9*0.85,"Alerta","Mal"))) -> Mal
A10: % conversión lead→venta | B10: =IFERROR(INDEX('Datos Semanales'!$AF$5:$AF$57,MATCH($B$3,'Datos Semanales'!$A$5:$A$57,0)),"") -> 0.018867925 | C10: 0.1 | D10: =IFERROR(INDEX('Datos Semanales'!$AF$5:$AF$57,MATCH($B$3-1,'Datos Semanales'!$A$5:$A$57,0)),"") -> 0.018518519 | E10: =IFERROR(B10-D10,"") -> 0.00034940601 | F10: =IF(B10="","",IF(B10>=C10,"Bien",IF(B10>=C10*0.85,"Alerta","Mal"))) -> Mal
A11: % leads contactados | B11: =IFERROR(INDEX('Datos Semanales'!$AH$5:$AH$57,MATCH($B$3,'Datos Semanales'!$A$5:$A$57,0)),"") -> 0.43396226 | C11: 0.8 | D11: =IFERROR(INDEX('Datos Semanales'!$AH$5:$AH$57,MATCH($B$3-1,'Datos Semanales'!$A$5:$A$57,0)),"") | E11: =IFERROR(B11-D11,"") | F11: =IF(B11="","",IF(B11>=C11,"Bien",IF(B11>=C11*0.85,"Alerta","Mal"))) -> Mal
A12: Leads sin trabajar | B12: =IFERROR(INDEX('Datos Semanales'!$AI$5:$AI$57,MATCH($B$3,'Datos Semanales'!$A$5:$A$57,0)),"") -> 30 | C12: 10 | D12: =IFERROR(INDEX('Datos Semanales'!$AI$5:$AI$57,MATCH($B$3-1,'Datos Semanales'!$A$5:$A$57,0)),"") | E12: =IFERROR(B12-D12,"") | F12: =IF(B12="","",IF(B12<=C12,"Bien",IF(B12<=C12*1.2,"Alerta","Mal"))) -> Mal
A13: % fuera de plazo | B13: =IFERROR(INDEX('Datos Semanales'!$T$5:$T$57,MATCH($B$3,'Datos Semanales'!$A$5:$A$57,0)),"") -> 0 | C13: 0.1 | D13: =IFERROR(INDEX('Datos Semanales'!$T$5:$T$57,MATCH($B$3-1,'Datos Semanales'!$A$5:$A$57,0)),"") | E13: =IFERROR(B13-D13,"") | F13: =IF(B13="","",IF(B13<=C13,"Bien",IF(B13<=C13*1.2,"Alerta","Mal"))) -> Bien
A14: % incidencias | B14: =IFERROR(INDEX('Datos Semanales'!$U$5:$U$57,MATCH($B$3,'Datos Semanales'!$A$5:$A$57,0)),"") | C14: 0.05 | D14: =IFERROR(INDEX('Datos Semanales'!$U$5:$U$57,MATCH($B$3-1,'Datos Semanales'!$A$5:$A$57,0)),"") -> 0.57142857 | E14: =IFERROR(B14-D14,"") | F14: =IF(B14="","",IF(B14<=C14,"Bien",IF(B14<=C14*1.2,"Alerta","Mal")))
A15: Pedidos atrasados (€) | B15: =IFERROR(INDEX('Datos Semanales'!$S$5:$S$57,MATCH($B$3,'Datos Semanales'!$A$5:$A$57,0)),"") -> 0 | C15: 5 | D15: =IFERROR(INDEX('Datos Semanales'!$S$5:$S$57,MATCH($B$3-1,'Datos Semanales'!$A$5:$A$57,0)),"") -> 0 | E15: =IFERROR(B15-D15,"") -> 0 | F15: =IF(B15="","",IF(B15<=C15,"Bien",IF(B15<=C15*1.2,"Alerta","Mal"))) -> Bien
A16: Carga fábrica (semanas) | B16: =IFERROR(INDEX('Datos Semanales'!$AA$5:$AA$57,MATCH($B$3,'Datos Semanales'!$A$5:$A$57,0)),"") -> 3.7513633 | C16: 4 | D16: =IFERROR(INDEX('Datos Semanales'!$AA$5:$AA$57,MATCH($B$3-1,'Datos Semanales'!$A$5:$A$57,0)),"") -> 3.8116587 | E16: =IFERROR(B16-D16,"") -> -0.060295333 | F16: =IF(B16="","",IF(AND(B16>=4,B16<=5),"Bien",IF(OR(AND(B16>=3,B16<4),AND(B16>5,B16<=6)),"Alerta","Mal"))) -> Alerta
A19: FOCO SEMANAL
A20: KPI prioritario
A21: Problema principal
A22: Acción concreta
A23: Responsable
A24: Fecha revisión

Sheet Plantilla Semana
A1: Plantilla de Revisión Semanal
A2: Formato vertical para reunión. Copiar o imprimir si se quiere revisar sin entrar al detalle.
A4: Área | B4: KPI | C4: Valor | D4: Objetivo | E4: Responsable | F4: Comentario | G4: Acción
A5: Ventas | B5: Ventas (€) | E5: Verónica
A6: Ventas | B6: % vs objetivo | E6: Verónica
A7: Marketing | B7: Leads generados | E7: Rafa
A8: Marketing | B8: CPL (€) | E8: Rafa
A9: Sistema Leads | B9: % contactados <24h | E9: Verónica / Sheila
A10: Sistema Leads | B10: Leads sin trabajar | E10: Verónica / Sheila
A11: Producción | B11: % fuera de plazo | E11: Manolo / Juan
A12: Producción | B12: % incidencias | E12: Manolo / Juan
A13: Producción | B13: Pedidos atrasados (€) | E13: Manolo / Juan
A14: Producción | B14: Carga fábrica (semanas) | E14: Manolo / Juan

Sheet Resumen Mensual
A1: Resumen Mensual
A2: Visión mensual rápida. Se calcula desde la hoja Datos Semanales.
A4: Mes | B4: Ventas totales (€) | C4: Objetivo ventas (€) | D4: % vs objetivo | E4: Ventas 2024 (€) | F4: % vs 2024 | G4: Leads totales | H4: % conversión lead→venta | I4: % incidencias | J4: % fuera de plazo | K4: Pedidos atrasados (€) | L4: Comentario
A5: Enero | B5: =SUMIF('Datos Semanales'!$B$5:$B$57,A5,'Datos Semanales'!$G$5:$G$57) -> 0 | C5: =SUMIF('Datos Semanales'!$B$5:$B$57,A5,'Datos Semanales'!$H$5:$H$57) -> 0 | D5: =IFERROR(B5/C5,0) -> 0 | E5: =SUMIF('Datos Semanales'!$B$5:$B$57,A5,'Datos Semanales'!$J$5:$J$57) -> 0 | F5: =IFERROR(B5/E5-1,0) -> 0 | G5: =SUMIF('Datos Semanales'!$B$5:$B$57,A5,'Datos Semanales'!$AB$5:$AB$57) -> 0 | H5: =IFERROR(AVERAGEIF('Datos Semanales'!$B$5:$B$57,A5,'Datos Semanales'!$AF$5:$AF$57),0) -> 0 | I5: =IFERROR(AVERAGEIF('Datos Semanales'!$B$5:$B$57,A5,'Datos Semanales'!$U$5:$U$57),0) -> 0 | J5: =IFERROR(AVERAGEIF('Datos Semanales'!$B$5:$B$57,A5,'Datos Semanales'!$T$5:$T$57),0) -> 0 | K5: =_xludf.MAXIFS('Datos Semanales'!$S$5:$S$57,'Datos Semanales'!$B$5:$B$57,A5) -> #NAME?
A6: Febrero | B6: =SUMIF('Datos Semanales'!$B$5:$B$57,A6,'Datos Semanales'!$G$5:$G$57) -> 0 | C6: =SUMIF('Datos Semanales'!$B$5:$B$57,A6,'Datos Semanales'!$H$5:$H$57) -> 0 | D6: =IFERROR(B6/C6,0) -> 0 | E6: =SUMIF('Datos Semanales'!$B$5:$B$57,A6,'Datos Semanales'!$J$5:$J$57) -> 0 | F6: =IFERROR(B6/E6-1,0) -> 0 | G6: =SUMIF('Datos Semanales'!$B$5:$B$57,A6,'Datos Semanales'!$AB$5:$AB$57) -> 0 | H6: =IFERROR(AVERAGEIF('Datos Semanales'!$B$5:$B$57,A6,'Datos Semanales'!$AF$5:$AF$57),0) -> 0 | I6: =IFERROR(AVERAGEIF('Datos Semanales'!$B$5:$B$57,A6,'Datos Semanales'!$U$5:$U$57),0) -> 0 | J6: =IFERROR(AVERAGEIF('Datos Semanales'!$B$5:$B$57,A6,'Datos Semanales'!$T$5:$T$57),0) -> 0 | K6: =_xludf.MAXIFS('Datos Semanales'!$S$5:$S$57,'Datos Semanales'!$B$5:$B$57,A6) -> #NAME?
A7: Marzo | B7: =SUMIF('Datos Semanales'!$B$5:$B$57,A7,'Datos Semanales'!$G$5:$G$57) -> 0 | C7: =SUMIF('Datos Semanales'!$B$5:$B$57,A7,'Datos Semanales'!$H$5:$H$57) -> 0 | D7: =IFERROR(B7/C7,0) -> 0 | E7: =SUMIF('Datos Semanales'!$B$5:$B$57,A7,'Datos Semanales'!$J$5:$J$57) -> 0 | F7: =IFERROR(B7/E7-1,0) -> 0 | G7: =SUMIF('Datos Semanales'!$B$5:$B$57,A7,'Datos Semanales'!$AB$5:$AB$57) -> 0 | H7: =IFERROR(AVERAGEIF('Datos Semanales'!$B$5:$B$57,A7,'Datos Semanales'!$AF$5:$AF$57),0) -> 0 | I7: =IFERROR(AVERAGEIF('Datos Semanales'!$B$5:$B$57,A7,'Datos Semanales'!$U$5:$U$57),0) -> 0 | J7: =IFERROR(AVERAGEIF('Datos Semanales'!$B$5:$B$57,A7,'Datos Semanales'!$T$5:$T$57),0) -> 0 | K7: =_xludf.MAXIFS('Datos Semanales'!$S$5:$S$57,'Datos Semanales'!$B$5:$B$57,A7) -> #NAME?
A8: Abril | B8: =SUMIF('Datos Semanales'!$B$5:$B$57,A8,'Datos Semanales'!$G$5:$G$57) -> 105793.88 | C8: =SUMIF('Datos Semanales'!$B$5:$B$57,A8,'Datos Semanales'!$H$5:$H$57) -> 93000 | D8: =IFERROR(B8/C8,0) -> 1.1375686 | E8: =SUMIF('Datos Semanales'!$B$5:$B$57,A8,'Datos Semanales'!$J$5:$J$57) -> 98400 | F8: =IFERROR(B8/E8-1,0) -> 0.075141057 | G8: =SUMIF('Datos Semanales'!$B$5:$B$57,A8,'Datos Semanales'!$AB$5:$AB$57) -> 107 | H8: =IFERROR(AVERAGEIF('Datos Semanales'!$B$5:$B$57,A8,'Datos Semanales'!$AF$5:$AF$57),0) -> 0.018693222 | I8: =IFERROR(AVERAGEIF('Datos Semanales'!$B$5:$B$57,A8,'Datos Semanales'!$U$5:$U$57),0) -> 0.57142857 | J8: =IFERROR(AVERAGEIF('Datos Semanales'!$B$5:$B$57,A8,'Datos Semanales'!$T$5:$T$57),0) -> 0 | K8: =_xludf.MAXIFS('Datos Semanales'!$S$5:$S$57,'Datos Semanales'!$B$5:$B$57,A8) -> #NAME?
A9: Mayo | B9: =SUMIF('Datos Semanales'!$B$5:$B$57,A9,'Datos Semanales'!$G$5:$G$57) -> 168094.37 | C9: =SUMIF('Datos Semanales'!$B$5:$B$57,A9,'Datos Semanales'!$H$5:$H$57) -> 186000 | D9: =IFERROR(B9/C9,0) -> 0.90373317 | E9: =SUMIF('Datos Semanales'!$B$5:$B$57,A9,'Datos Semanales'!$J$5:$J$57) -> 220548.71 | F9: =IFERROR(B9/E9-1,0) -> -0.23783562 | G9: =SUMIF('Datos Semanales'!$B$5:$B$57,A9,'Datos Semanales'!$AB$5:$AB$57) -> 156 | H9: =IFERROR(AVERAGEIF('Datos Semanales'!$B$5:$B$57,A9,'Datos Semanales'!$AF$5:$AF$57),0) -> 0.037884566 | I9: =IFERROR(AVERAGEIF('Datos Semanales'!$B$5:$B$57,A9,'Datos Semanales'!$U$5:$U$57),0) -> 0.40461339 | J9: =IFERROR(AVERAGEIF('Datos Semanales'!$B$5:$B$57,A9,'Datos Semanales'!$T$5:$T$57),0) -> 0.075820205 | K9: =_xludf.MAXIFS('Datos Semanales'!$S$5:$S$57,'Datos Semanales'!$B$5:$B$57,A9) -> #NAME?
A10: Junio | B10: =SUMIF('Datos Semanales'!$B$5:$B$57,A10,'Datos Semanales'!$G$5:$G$57) -> 167019 | C10: =SUMIF('Datos Semanales'!$B$5:$B$57,A10,'Datos Semanales'!$H$5:$H$57) -> 232500 | D10: =IFERROR(B10/C10,0) -> 0.71836129 | E10: =SUMIF('Datos Semanales'!$B$5:$B$57,A10,'Datos Semanales'!$J$5:$J$57) -> 203309 | F10: =IFERROR(B10/E10-1,0) -> -0.17849677 | G10: =SUMIF('Datos Semanales'!$B$5:$B$57,A10,'Datos Semanales'!$AB$5:$AB$57) -> 0 | H10: =IFERROR(AVERAGEIF('Datos Semanales'!$B$5:$B$57,A10,'Datos Semanales'!$AF$5:$AF$57),0) -> 0 | I10: =IFERROR(AVERAGEIF('Datos Semanales'!$B$5:$B$57,A10,'Datos Semanales'!$U$5:$U$57),0) -> 0.39426594 | J10: =IFERROR(AVERAGEIF('Datos Semanales'!$B$5:$B$57,A10,'Datos Semanales'!$T$5:$T$57),0) -> 0.035548301 | K10: =_xludf.MAXIFS('Datos Semanales'!$S$5:$S$57,'Datos Semanales'!$B$5:$B$57,A10) -> #NAME?
A11: Julio | B11: =SUMIF('Datos Semanales'!$B$5:$B$57,A11,'Datos Semanales'!$G$5:$G$57) -> 60535 | C11: =SUMIF('Datos Semanales'!$B$5:$B$57,A11,'Datos Semanales'!$H$5:$H$57) -> 186000 | D11: =IFERROR(B11/C11,0) -> 0.32545699 | E11: =SUMIF('Datos Semanales'!$B$5:$B$57,A11,'Datos Semanales'!$J$5:$J$57) -> 179772 | F11: =IFERROR(B11/E11-1,0) -> -0.66326792 | G11: =SUMIF('Datos Semanales'!$B$5:$B$57,A11,'Datos Semanales'!$AB$5:$AB$57) -> 0 | H11: =IFERROR(AVERAGEIF('Datos Semanales'!$B$5:$B$57,A11,'Datos Semanales'!$AF$5:$AF$57),0) -> 0 | I11: =IFERROR(AVERAGEIF('Datos Semanales'!$B$5:$B$57,A11,'Datos Semanales'!$U$5:$U$57),0) -> 0.89583333 | J11: =IFERROR(AVERAGEIF('Datos Semanales'!$B$5:$B$57,A11,'Datos Semanales'!$T$5:$T$57),0) -> 0.099314523 | K11: =_xludf.MAXIFS('Datos Semanales'!$S$5:$S$57,'Datos Semanales'!$B$5:$B$57,A11) -> #NAME?
A12: Agosto | B12: =SUMIF('Datos Semanales'!$B$5:$B$57,A12,'Datos Semanales'!$G$5:$G$57) -> 49990 | C12: =SUMIF('Datos Semanales'!$B$5:$B$57,A12,'Datos Semanales'!$H$5:$H$57) -> 224500 | D12: =IFERROR(B12/C12,0) -> 0.22267261 | E12: =SUMIF('Datos Semanales'!$B$5:$B$57,A12,'Datos Semanales'!$J$5:$J$57) -> 85514 | F12: =IFERROR(B12/E12-1,0) -> -0.41541736 | G12: =SUMIF('Datos Semanales'!$B$5:$B$57,A12,'Datos Semanales'!$AB$5:$AB$57) -> 0 | H12: =IFERROR(AVERAGEIF('Datos Semanales'!$B$5:$B$57,A12,'Datos Semanales'!$AF$5:$AF$57),0) -> 0 | I12: =IFERROR(AVERAGEIF('Datos Semanales'!$B$5:$B$57,A12,'Datos Semanales'!$U$5:$U$57),0) -> 0 | J12: =IFERROR(AVERAGEIF('Datos Semanales'!$B$5:$B$57,A12,'Datos Semanales'!$T$5:$T$57),0) -> 0 | K12: =_xludf.MAXIFS('Datos Semanales'!$S$5:$S$57,'Datos Semanales'!$B$5:$B$57,A12) -> #NAME?
A13: Septiembre | B13: =SUMIF('Datos Semanales'!$B$5:$B$57,A13,'Datos Semanales'!$G$5:$G$57) -> 138625 | C13: =SUMIF('Datos Semanales'!$B$5:$B$57,A13,'Datos Semanales'!$H$5:$H$57) -> 232500 | D13: =IFERROR(B13/C13,0) -> 0.59623656 | E13: =SUMIF('Datos Semanales'!$B$5:$B$57,A13,'Datos Semanales'!$J$5:$J$57) -> 201515 | F13: =IFERROR(B13/E13-1,0) -> -0.31208595 | G13: =SUMIF('Datos Semanales'!$B$5:$B$57,A13,'Datos Semanales'!$AB$5:$AB$57) -> 0 | H13: =IFERROR(AVERAGEIF('Datos Semanales'!$B$5:$B$57,A13,'Datos Semanales'!$AF$5:$AF$57),0) -> 0 | I13: =IFERROR(AVERAGEIF('Datos Semanales'!$B$5:$B$57,A13,'Datos Semanales'!$U$5:$U$57),0) -> 0 | J13: =IFERROR(AVERAGEIF('Datos Semanales'!$B$5:$B$57,A13,'Datos Semanales'!$T$5:$T$57),0) -> 0 | K13: =_xludf.MAXIFS('Datos Semanales'!$S$5:$S$57,'Datos Semanales'!$B$5:$B$57,A13) -> #NAME?
A14: Octubre | B14: =SUMIF('Datos Semanales'!$B$5:$B$57,A14,'Datos Semanales'!$G$5:$G$57) -> 19905 | C14: =SUMIF('Datos Semanales'!$B$5:$B$57,A14,'Datos Semanales'!$H$5:$H$57) -> 46500 | D14: =IFERROR(B14/C14,0) -> 0.42806452 | E14: =SUMIF('Datos Semanales'!$B$5:$B$57,A14,'Datos Semanales'!$J$5:$J$57) -> 44073.75 | F14: =IFERROR(B14/E14-1,0) -> -0.54837063 | G14: =SUMIF('Datos Semanales'!$B$5:$B$57,A14,'Datos Semanales'!$AB$5:$AB$57) -> 0 | H14: =IFERROR(AVERAGEIF('Datos Semanales'!$B$5:$B$57,A14,'Datos Semanales'!$AF$5:$AF$57),0) -> 0 | I14: =IFERROR(AVERAGEIF('Datos Semanales'!$B$5:$B$57,A14,'Datos Semanales'!$U$5:$U$57),0) -> 0 | J14: =IFERROR(AVERAGEIF('Datos Semanales'!$B$5:$B$57,A14,'Datos Semanales'!$T$5:$T$57),0) -> 0 | K14: =_xludf.MAXIFS('Datos Semanales'!$S$5:$S$57,'Datos Semanales'!$B$5:$B$57,A14) -> #NAME?
A15: Noviembre | B15: =SUMIF('Datos Semanales'!$B$5:$B$57,A15,'Datos Semanales'!$G$5:$G$57) -> 0 | C15: =SUMIF('Datos Semanales'!$B$5:$B$57,A15,'Datos Semanales'!$H$5:$H$57) -> 0 | D15: =IFERROR(B15/C15,0) -> 0 | E15: =SUMIF('Datos Semanales'!$B$5:$B$57,A15,'Datos Semanales'!$J$5:$J$57) -> 0 | F15: =IFERROR(B15/E15-1,0) -> 0 | G15: =SUMIF('Datos Semanales'!$B$5:$B$57,A15,'Datos Semanales'!$AB$5:$AB$57) -> 0 | H15: =IFERROR(AVERAGEIF('Datos Semanales'!$B$5:$B$57,A15,'Datos Semanales'!$AF$5:$AF$57),0) -> 0 | I15: =IFERROR(AVERAGEIF('Datos Semanales'!$B$5:$B$57,A15,'Datos Semanales'!$U$5:$U$57),0) -> 0 | J15: =IFERROR(AVERAGEIF('Datos Semanales'!$B$5:$B$57,A15,'Datos Semanales'!$T$5:$T$57),0) -> 0 | K15: =_xludf.MAXIFS('Datos Semanales'!$S$5:$S$57,'Datos Semanales'!$B$5:$B$57,A15) -> #NAME?
A16: Diciembre | B16: =SUMIF('Datos Semanales'!$B$5:$B$57,A16,'Datos Semanales'!$G$5:$G$57) -> 0 | C16: =SUMIF('Datos Semanales'!$B$5:$B$57,A16,'Datos Semanales'!$H$5:$H$57) -> 0 | D16: =IFERROR(B16/C16,0) -> 0 | E16: =SUMIF('Datos Semanales'!$B$5:$B$57,A16,'Datos Semanales'!$J$5:$J$57) -> 0 | F16: =IFERROR(B16/E16-1,0) -> 0 | G16: =SUMIF('Datos Semanales'!$B$5:$B$57,A16,'Datos Semanales'!$AB$5:$AB$57) -> 0 | H16: =IFERROR(AVERAGEIF('Datos Semanales'!$B$5:$B$57,A16,'Datos Semanales'!$AF$5:$AF$57),0) -> 0 | I16: =IFERROR(AVERAGEIF('Datos Semanales'!$B$5:$B$57,A16,'Datos Semanales'!$U$5:$U$57),0) -> 0 | J16: =IFERROR(AVERAGEIF('Datos Semanales'!$B$5:$B$57,A16,'Datos Semanales'!$T$5:$T$57),0) -> 0 | K16: =_xludf.MAXIFS('Datos Semanales'!$S$5:$S$57,'Datos Semanales'!$B$5:$B$57,A16) -> #NAME?
